2019-06-27 09:17:45,913 ERROR: Exception on /auth/login [GET] [in c:\users\prime sources\documents\python_projects\flaskmicroblog\microblogvenv\lib\site-packages\flask\app.py:1780]
Traceback (most recent call last):
  File "c:\users\prime sources\documents\python_projects\flaskmicroblog\microblogvenv\lib\site-packages\flask\app.py", line 2311, in wsgi_app
    response = self.full_dispatch_request()
  File "c:\users\prime sources\documents\python_projects\flaskmicroblog\microblogvenv\lib\site-packages\flask\app.py", line 1834, in full_dispatch_request
    rv = self.handle_user_exception(e)
  File "c:\users\prime sources\documents\python_projects\flaskmicroblog\microblogvenv\lib\site-packages\flask\app.py", line 1737, in handle_user_exception
    reraise(exc_type, exc_value, tb)
  File "c:\users\prime sources\documents\python_projects\flaskmicroblog\microblogvenv\lib\site-packages\flask\_compat.py", line 36, in reraise
    raise value
  File "c:\users\prime sources\documents\python_projects\flaskmicroblog\microblogvenv\lib\site-packages\flask\app.py", line 1832, in full_dispatch_request
    rv = self.dispatch_request()
  File "c:\users\prime sources\documents\python_projects\flaskmicroblog\microblogvenv\lib\site-packages\flask\app.py", line 1818, in dispatch_request
    return self.view_functions[rule.endpoint](**req.view_args)
  File "C:\Users\Prime Sources\Documents\Python_Projects\flaskmicroblog\app\auth\routes.py", line 28, in login
    return render_template('auth/login.html', title=_('Sign In'), form=form)
  File "c:\users\prime sources\documents\python_projects\flaskmicroblog\microblogvenv\lib\site-packages\flask\templating.py", line 135, in render_template
    context, ctx.app)
  File "c:\users\prime sources\documents\python_projects\flaskmicroblog\microblogvenv\lib\site-packages\flask\templating.py", line 117, in _render
    rv = template.render(context)
  File "c:\users\prime sources\documents\python_projects\flaskmicroblog\microblogvenv\lib\site-packages\jinja2\asyncsupport.py", line 76, in render
    return original_render(self, *args, **kwargs)
  File "c:\users\prime sources\documents\python_projects\flaskmicroblog\microblogvenv\lib\site-packages\jinja2\environment.py", line 1008, in render
    return self.environment.handle_exception(exc_info, True)
  File "c:\users\prime sources\documents\python_projects\flaskmicroblog\microblogvenv\lib\site-packages\jinja2\environment.py", line 780, in handle_exception
    reraise(exc_type, exc_value, tb)
  File "c:\users\prime sources\documents\python_projects\flaskmicroblog\microblogvenv\lib\site-packages\jinja2\_compat.py", line 37, in reraise
    raise value.with_traceback(tb)
  File "C:\Users\Prime Sources\Documents\Python_Projects\flaskmicroblog\app\templates\auth\login.html", line 2, in top-level template code
    {% import 'bootstrap/wtf.html' as wtf %}
  File "C:\Users\Prime Sources\Documents\Python_Projects\flaskmicroblog\app\templates\base.html", line 1, in top-level template code
    {% extends 'bootstrap/base.html' %}
  File "c:\users\prime sources\documents\python_projects\flaskmicroblog\microblogvenv\lib\site-packages\flask_bootstrap\templates\bootstrap\base.html", line 1, in top-level template code
    {% block doc -%}
  File "c:\users\prime sources\documents\python_projects\flaskmicroblog\microblogvenv\lib\site-packages\flask_bootstrap\templates\bootstrap\base.html", line 4, in block "doc"
    {%- block html %}
  File "c:\users\prime sources\documents\python_projects\flaskmicroblog\microblogvenv\lib\site-packages\flask_bootstrap\templates\bootstrap\base.html", line 20, in block "html"
    {% block body -%}
  File "c:\users\prime sources\documents\python_projects\flaskmicroblog\microblogvenv\lib\site-packages\flask_bootstrap\templates\bootstrap\base.html", line 23, in block "body"
    {% block content -%}
  File "C:\Users\Prime Sources\Documents\Python_Projects\flaskmicroblog\app\templates\base.html", line 48, in block "content"
    {% block app_content %}{% endblock %}
  File "C:\Users\Prime Sources\Documents\Python_Projects\flaskmicroblog\app\templates\auth\login.html", line 12, in block "app_content"
    <p>{{ _('New User?') }} <a href="{{ url_for('register') }}">{{ _('Click to Register!') }}</a></p>
  File "c:\users\prime sources\documents\python_projects\flaskmicroblog\microblogvenv\lib\site-packages\flask\helpers.py", line 356, in url_for
    return appctx.app.handle_url_build_error(error, endpoint, values)
  File "c:\users\prime sources\documents\python_projects\flaskmicroblog\microblogvenv\lib\site-packages\flask\app.py", line 2080, in handle_url_build_error
    reraise(exc_type, exc_value, tb)
  File "c:\users\prime sources\documents\python_projects\flaskmicroblog\microblogvenv\lib\site-packages\flask\_compat.py", line 36, in reraise
    raise value
  File "c:\users\prime sources\documents\python_projects\flaskmicroblog\microblogvenv\lib\site-packages\flask\helpers.py", line 345, in url_for
    force_external=external)
  File "c:\users\prime sources\documents\python_projects\flaskmicroblog\microblogvenv\lib\site-packages\werkzeug\routing.py", line 2007, in build
    raise BuildError(endpoint, values, method, self)
werkzeug.routing.BuildError: Could not build url for endpoint 'register'. Did you mean 'auth.register' instead?
2019-06-27 09:19:09,558 INFO: Microblog startup [in C:\Users\Prime Sources\Documents\Python_Projects\flaskmicroblog\app\__init__.py:74]
2019-06-27 09:20:26,505 INFO: Microblog startup [in C:\Users\Prime Sources\Documents\Python_Projects\flaskmicroblog\app\__init__.py:74]
2019-06-27 09:20:35,155 INFO: Microblog startup [in C:\Users\Prime Sources\Documents\Python_Projects\flaskmicroblog\app\__init__.py:74]
2019-06-27 09:24:02,430 INFO: Microblog startup [in C:\Users\Prime Sources\Documents\Python_Projects\flaskmicroblog\app\__init__.py:74]
2019-06-27 10:58:29,927 INFO: Microblog startup [in C:\Users\Prime Sources\Documents\Python_Projects\flaskmicroblog\app\__init__.py:74]
2019-06-28 17:14:56,327 INFO: Microblog startup [in C:\Users\Prime Sources\Documents\Python_Projects\flaskmicroblog\app\__init__.py:75]
2019-06-28 17:20:46,526 INFO: Microblog startup [in C:\Users\Prime Sources\Documents\Python_Projects\flaskmicroblog\app\__init__.py:75]
2019-06-28 17:24:32,222 INFO: Microblog startup [in C:\Users\Prime Sources\Documents\Python_Projects\flaskmicroblog\app\__init__.py:75]
2019-07-04 05:20:04,122 INFO: Microblog startup [in /home/uferepeace/Documents/projects/FlaskMicroBlog/app/__init__.py:75]
2019-07-04 05:21:28,840 INFO: Microblog startup [in /home/uferepeace/Documents/projects/FlaskMicroBlog/app/__init__.py:75]
2019-07-04 05:22:39,547 INFO: Microblog startup [in /home/uferepeace/Documents/projects/FlaskMicroBlog/app/__init__.py:75]
2019-07-04 05:50:24,578 INFO: Microblog startup [in /home/uferepeace/Documents/projects/FlaskMicroBlog/app/__init__.py:75]
2019-07-04 05:50:52,453 ERROR: Exception on /search [GET] [in /home/uferepeace/Documents/projects/FlaskMicroBlog/microblogvenv/lib/python3.7/site-packages/flask/app.py:1780]
Traceback (most recent call last):
  File "/home/uferepeace/Documents/projects/FlaskMicroBlog/microblogvenv/lib/python3.7/site-packages/flask/app.py", line 2311, in wsgi_app
    response = self.full_dispatch_request()
  File "/home/uferepeace/Documents/projects/FlaskMicroBlog/microblogvenv/lib/python3.7/site-packages/flask/app.py", line 1834, in full_dispatch_request
    rv = self.handle_user_exception(e)
  File "/home/uferepeace/Documents/projects/FlaskMicroBlog/microblogvenv/lib/python3.7/site-packages/flask/app.py", line 1737, in handle_user_exception
    reraise(exc_type, exc_value, tb)
  File "/home/uferepeace/Documents/projects/FlaskMicroBlog/microblogvenv/lib/python3.7/site-packages/flask/_compat.py", line 36, in reraise
    raise value
  File "/home/uferepeace/Documents/projects/FlaskMicroBlog/microblogvenv/lib/python3.7/site-packages/flask/app.py", line 1832, in full_dispatch_request
    rv = self.dispatch_request()
  File "/home/uferepeace/Documents/projects/FlaskMicroBlog/microblogvenv/lib/python3.7/site-packages/flask/app.py", line 1818, in dispatch_request
    return self.view_functions[rule.endpoint](**req.view_args)
  File "/home/uferepeace/Documents/projects/FlaskMicroBlog/microblogvenv/lib/python3.7/site-packages/flask_login/utils.py", line 261, in decorated_view
    return func(*args, **kwargs)
  File "/home/uferepeace/Documents/projects/FlaskMicroBlog/app/main/routes.py", line 144, in search
    current_app.config['POSTS_PER_PAGE'])
  File "/home/uferepeace/Documents/projects/FlaskMicroBlog/app/models.py", line 20, in search
    ids, total = query_index(cls.__tablename__, expression, page, per_page)
  File "/home/uferepeace/Documents/projects/FlaskMicroBlog/app/search.py", line 23, in query_index
    'from': (page - 1) * per_page, 'size': per_page})
  File "/home/uferepeace/Documents/projects/FlaskMicroBlog/microblogvenv/lib/python3.7/site-packages/elasticsearch/client/utils.py", line 84, in _wrapped
    return func(*args, params=params, **kwargs)
TypeError: search() got an unexpected keyword argument 'doc_type'
