2019-06-27 09:00:42,672 ERROR: Exception on / [GET] [in c:\users\prime sources\documents\python_projects\flaskmicroblog\microblogvenv\lib\site-packages\flask\app.py:1780]
Traceback (most recent call last):
  File "c:\users\prime sources\documents\python_projects\flaskmicroblog\microblogvenv\lib\site-packages\flask\app.py", line 2311, in wsgi_app
    response = self.full_dispatch_request()
  File "c:\users\prime sources\documents\python_projects\flaskmicroblog\microblogvenv\lib\site-packages\flask\app.py", line 1834, in full_dispatch_request
    rv = self.handle_user_exception(e)
  File "c:\users\prime sources\documents\python_projects\flaskmicroblog\microblogvenv\lib\site-packages\flask\app.py", line 1737, in handle_user_exception
    reraise(exc_type, exc_value, tb)
  File "c:\users\prime sources\documents\python_projects\flaskmicroblog\microblogvenv\lib\site-packages\flask\_compat.py", line 36, in reraise
    raise value
  File "c:\users\prime sources\documents\python_projects\flaskmicroblog\microblogvenv\lib\site-packages\flask\app.py", line 1832, in full_dispatch_request
    rv = self.dispatch_request()
  File "c:\users\prime sources\documents\python_projects\flaskmicroblog\microblogvenv\lib\site-packages\flask\app.py", line 1818, in dispatch_request
    return self.view_functions[rule.endpoint](**req.view_args)
  File "c:\users\prime sources\documents\python_projects\flaskmicroblog\microblogvenv\lib\site-packages\flask_login\utils.py", line 261, in decorated_view
    return func(*args, **kwargs)
  File "C:\Users\Prime Sources\Documents\Python_Projects\flaskmicroblog\app\main\routes.py", line 46, in index
    prev_url=prev_url)
  File "c:\users\prime sources\documents\python_projects\flaskmicroblog\microblogvenv\lib\site-packages\flask\templating.py", line 135, in render_template
    context, ctx.app)
  File "c:\users\prime sources\documents\python_projects\flaskmicroblog\microblogvenv\lib\site-packages\flask\templating.py", line 117, in _render
    rv = template.render(context)
  File "c:\users\prime sources\documents\python_projects\flaskmicroblog\microblogvenv\lib\site-packages\jinja2\asyncsupport.py", line 76, in render
    return original_render(self, *args, **kwargs)
  File "c:\users\prime sources\documents\python_projects\flaskmicroblog\microblogvenv\lib\site-packages\jinja2\environment.py", line 1008, in render
    return self.environment.handle_exception(exc_info, True)
  File "c:\users\prime sources\documents\python_projects\flaskmicroblog\microblogvenv\lib\site-packages\jinja2\environment.py", line 780, in handle_exception
    reraise(exc_type, exc_value, tb)
  File "c:\users\prime sources\documents\python_projects\flaskmicroblog\microblogvenv\lib\site-packages\jinja2\_compat.py", line 37, in reraise
    raise value.with_traceback(tb)
  File "C:\Users\Prime Sources\Documents\Python_Projects\flaskmicroblog\app\templates\index.html", line 2, in top-level template code
    {% import 'bootstrap/wtf.html' as wtf %}
  File "C:\Users\Prime Sources\Documents\Python_Projects\flaskmicroblog\app\templates\base.html", line 1, in top-level template code
    {% extends 'bootstrap/base.html' %}
  File "c:\users\prime sources\documents\python_projects\flaskmicroblog\microblogvenv\lib\site-packages\flask_bootstrap\templates\bootstrap\base.html", line 1, in top-level template code
    {% block doc -%}
  File "c:\users\prime sources\documents\python_projects\flaskmicroblog\microblogvenv\lib\site-packages\flask_bootstrap\templates\bootstrap\base.html", line 4, in block "doc"
    {%- block html %}
  File "c:\users\prime sources\documents\python_projects\flaskmicroblog\microblogvenv\lib\site-packages\flask_bootstrap\templates\bootstrap\base.html", line 20, in block "html"
    {% block body -%}
  File "c:\users\prime sources\documents\python_projects\flaskmicroblog\microblogvenv\lib\site-packages\flask_bootstrap\templates\bootstrap\base.html", line 23, in block "body"
    {% block content -%}
  File "C:\Users\Prime Sources\Documents\Python_Projects\flaskmicroblog\app\templates\base.html", line 48, in block "content"
    {% block app_content %}{% endblock %}
  File "C:\Users\Prime Sources\Documents\Python_Projects\flaskmicroblog\app\templates\index.html", line 11, in block "app_content"
    {% include '_post.html' %}
  File "C:\Users\Prime Sources\Documents\Python_Projects\flaskmicroblog\app\templates\_post.html", line 4, in top-level template code
    <a href="{{ url_for('user', username=post.author.username) }}">
  File "c:\users\prime sources\documents\python_projects\flaskmicroblog\microblogvenv\lib\site-packages\flask\helpers.py", line 356, in url_for
    return appctx.app.handle_url_build_error(error, endpoint, values)
  File "c:\users\prime sources\documents\python_projects\flaskmicroblog\microblogvenv\lib\site-packages\flask\app.py", line 2080, in handle_url_build_error
    reraise(exc_type, exc_value, tb)
  File "c:\users\prime sources\documents\python_projects\flaskmicroblog\microblogvenv\lib\site-packages\flask\_compat.py", line 36, in reraise
    raise value
  File "c:\users\prime sources\documents\python_projects\flaskmicroblog\microblogvenv\lib\site-packages\flask\helpers.py", line 345, in url_for
    force_external=external)
  File "c:\users\prime sources\documents\python_projects\flaskmicroblog\microblogvenv\lib\site-packages\werkzeug\routing.py", line 2007, in build
    raise BuildError(endpoint, values, method, self)
werkzeug.routing.BuildError: Could not build url for endpoint 'user' with values ['username']. Did you mean 'main.user' instead?
