2019-07-11 17:48:03,522 ERROR: Exception on /user/peace [GET] [in c:\users\prime sources\documents\python_projects\flaskmicroblog\microblogvenv\lib\site-packages\flask\app.py:1780]
Traceback (most recent call last):
  File "c:\users\prime sources\documents\python_projects\flaskmicroblog\microblogvenv\lib\site-packages\sqlalchemy\engine\base.py", line 1244, in _execute_context
    cursor, statement, parameters, context
  File "c:\users\prime sources\documents\python_projects\flaskmicroblog\microblogvenv\lib\site-packages\sqlalchemy\engine\default.py", line 550, in do_execute
    cursor.execute(statement, parameters)
sqlite3.OperationalError: no such column: user.last_message_read_time

The above exception was the direct cause of the following exception:

Traceback (most recent call last):
  File "c:\users\prime sources\documents\python_projects\flaskmicroblog\microblogvenv\lib\site-packages\flask\app.py", line 2311, in wsgi_app
    response = self.full_dispatch_request()
  File "c:\users\prime sources\documents\python_projects\flaskmicroblog\microblogvenv\lib\site-packages\flask\app.py", line 1834, in full_dispatch_request
    rv = self.handle_user_exception(e)
  File "c:\users\prime sources\documents\python_projects\flaskmicroblog\microblogvenv\lib\site-packages\flask\app.py", line 1737, in handle_user_exception
    reraise(exc_type, exc_value, tb)
  File "c:\users\prime sources\documents\python_projects\flaskmicroblog\microblogvenv\lib\site-packages\flask\_compat.py", line 36, in reraise
    raise value
  File "c:\users\prime sources\documents\python_projects\flaskmicroblog\microblogvenv\lib\site-packages\flask\app.py", line 1830, in full_dispatch_request
    rv = self.preprocess_request()
  File "c:\users\prime sources\documents\python_projects\flaskmicroblog\microblogvenv\lib\site-packages\flask\app.py", line 2106, in preprocess_request
    rv = func()
  File "C:\Users\Prime Sources\Documents\Python_Projects\flaskmicroblog\app\main\routes.py", line 16, in before_request
    if current_user.is_authenticated:
  File "c:\users\prime sources\documents\python_projects\flaskmicroblog\microblogvenv\lib\site-packages\werkzeug\local.py", line 348, in __getattr__
    return getattr(self._get_current_object(), name)
  File "c:\users\prime sources\documents\python_projects\flaskmicroblog\microblogvenv\lib\site-packages\werkzeug\local.py", line 307, in _get_current_object
    return self.__local()
  File "c:\users\prime sources\documents\python_projects\flaskmicroblog\microblogvenv\lib\site-packages\flask_login\utils.py", line 26, in <lambda>
    current_user = LocalProxy(lambda: _get_user())
  File "c:\users\prime sources\documents\python_projects\flaskmicroblog\microblogvenv\lib\site-packages\flask_login\utils.py", line 335, in _get_user
    current_app.login_manager._load_user()
  File "c:\users\prime sources\documents\python_projects\flaskmicroblog\microblogvenv\lib\site-packages\flask_login\login_manager.py", line 359, in _load_user
    return self.reload_user()
  File "c:\users\prime sources\documents\python_projects\flaskmicroblog\microblogvenv\lib\site-packages\flask_login\login_manager.py", line 321, in reload_user
    user = self.user_callback(user_id)
  File "C:\Users\Prime Sources\Documents\Python_Projects\flaskmicroblog\app\models.py", line 151, in load_user
    return User.query.get(int(id))
  File "c:\users\prime sources\documents\python_projects\flaskmicroblog\microblogvenv\lib\site-packages\sqlalchemy\orm\query.py", line 959, in get
    return self._get_impl(ident, loading.load_on_pk_identity)
  File "c:\users\prime sources\documents\python_projects\flaskmicroblog\microblogvenv\lib\site-packages\sqlalchemy\orm\query.py", line 1069, in _get_impl
    return db_load_fn(self, primary_key_identity)
  File "c:\users\prime sources\documents\python_projects\flaskmicroblog\microblogvenv\lib\site-packages\sqlalchemy\orm\loading.py", line 282, in load_on_pk_identity
    return q.one()
  File "c:\users\prime sources\documents\python_projects\flaskmicroblog\microblogvenv\lib\site-packages\sqlalchemy\orm\query.py", line 3281, in one
    ret = self.one_or_none()
  File "c:\users\prime sources\documents\python_projects\flaskmicroblog\microblogvenv\lib\site-packages\sqlalchemy\orm\query.py", line 3250, in one_or_none
    ret = list(self)
  File "c:\users\prime sources\documents\python_projects\flaskmicroblog\microblogvenv\lib\site-packages\sqlalchemy\orm\query.py", line 3323, in __iter__
    return self._execute_and_instances(context)
  File "c:\users\prime sources\documents\python_projects\flaskmicroblog\microblogvenv\lib\site-packages\sqlalchemy\orm\query.py", line 3348, in _execute_and_instances
    result = conn.execute(querycontext.statement, self._params)
  File "c:\users\prime sources\documents\python_projects\flaskmicroblog\microblogvenv\lib\site-packages\sqlalchemy\engine\base.py", line 988, in execute
    return meth(self, multiparams, params)
  File "c:\users\prime sources\documents\python_projects\flaskmicroblog\microblogvenv\lib\site-packages\sqlalchemy\sql\elements.py", line 287, in _execute_on_connection
    return connection._execute_clauseelement(self, multiparams, params)
  File "c:\users\prime sources\documents\python_projects\flaskmicroblog\microblogvenv\lib\site-packages\sqlalchemy\engine\base.py", line 1107, in _execute_clauseelement
    distilled_params,
  File "c:\users\prime sources\documents\python_projects\flaskmicroblog\microblogvenv\lib\site-packages\sqlalchemy\engine\base.py", line 1248, in _execute_context
    e, statement, parameters, cursor, context
  File "c:\users\prime sources\documents\python_projects\flaskmicroblog\microblogvenv\lib\site-packages\sqlalchemy\engine\base.py", line 1466, in _handle_dbapi_exception
    util.raise_from_cause(sqlalchemy_exception, exc_info)
  File "c:\users\prime sources\documents\python_projects\flaskmicroblog\microblogvenv\lib\site-packages\sqlalchemy\util\compat.py", line 383, in raise_from_cause
    reraise(type(exception), exception, tb=exc_tb, cause=cause)
  File "c:\users\prime sources\documents\python_projects\flaskmicroblog\microblogvenv\lib\site-packages\sqlalchemy\util\compat.py", line 128, in reraise
    raise value.with_traceback(tb)
  File "c:\users\prime sources\documents\python_projects\flaskmicroblog\microblogvenv\lib\site-packages\sqlalchemy\engine\base.py", line 1244, in _execute_context
    cursor, statement, parameters, context
  File "c:\users\prime sources\documents\python_projects\flaskmicroblog\microblogvenv\lib\site-packages\sqlalchemy\engine\default.py", line 550, in do_execute
    cursor.execute(statement, parameters)
sqlalchemy.exc.OperationalError: (sqlite3.OperationalError) no such column: user.last_message_read_time
[SQL: SELECT user.id AS user_id, user.username AS user_username, user.email AS user_email, user.password_hash AS user_password_hash, user.about_me AS user_about_me, user.last_seen AS user_last_seen, user.last_message_read_time AS user_last_message_read_time 
FROM user 
WHERE user.id = ?]
[parameters: (2,)]
(Background on this error at: http://sqlalche.me/e/e3q8)
2019-07-11 17:58:11,891 INFO: Microblog startup [in C:\Users\Prime Sources\Documents\Python_Projects\flaskmicroblog\app\__init__.py:75]
2019-07-11 17:58:36,557 INFO: Microblog startup [in C:\Users\Prime Sources\Documents\Python_Projects\flaskmicroblog\app\__init__.py:75]
2019-07-11 17:58:51,262 INFO: Microblog startup [in C:\Users\Prime Sources\Documents\Python_Projects\flaskmicroblog\app\__init__.py:75]
2019-07-12 16:27:02,460 INFO: Microblog startup [in C:\Users\Prime Sources\Documents\Python_Projects\flaskmicroblog\app\__init__.py:75]
2019-07-12 16:27:26,307 INFO: Microblog startup [in C:\Users\Prime Sources\Documents\Python_Projects\flaskmicroblog\app\__init__.py:75]
